Workbook
Name Ro: '2017_Clean_Data_Analysis'!$A:$A
Name RowI: '2016_Clean_Data_Analysis'!$A:$A
Name RowID: '2014_Clean_Data_Analysis'!$A$2:$A$1993
Name RowID2: '2015_Clean_Data_Analysis'!$A:$A
Name RowID3: '2016_Clean_Data_Analysis'!$A:$A
Name RowID4: '2017_Clean_Data_Analysis'!$A:$A
Name Year_2014: '2014_Clean_Data_Analysis'!$A$1997
Name Year_2015: '2015_Clean_Data_Analysis'!$A$2107
Name Year_2016: '2016_Clean_Data_Analysis'!$A$2592
Name Year_2017: '2017_Clean_Data_Analysis'!$A$3316
Name Year_2024: '2014_Clean_Data_Analysis'!$A$1997

Sheet 2014_Clean_Data_Analysis
A1: Row ID | B1: Order ID | C1: Order Date | D1: Month Number | E1: Product ID | F1: Product Name | G1: Category | H1: Sub-Category | I1: Customer ID | J1: Segment | K1: Quantity | L1: Ship Date | M1: Shipping Days | N1: Ship Mode | O1: Country | P1: State | Q1: Region | R1: City | S1: Discount | T1: Sales | U1: Profit | V1: Profit Margin
A2: 1 | B2: CA-2014-103800 | C2: 41642 | D2: =MONTH(Table12[[#This Row],[Order Date]]) -> 1 | E2: OFF-PA-10000174 | F2: Message Book, Wirebound, Four 5 1/2" X 4" Forms/Pg., 200 Dupl. Sets/Book | G2: Office Supplies | H2: Paper | I2: DP-13000 | J2: Consumer | K2: 2 | L2: 41646 | M2: =Table12[[#This Row],[Ship Date]]-Table12[[#This Row],[Order Date]] -> 4 | N2: Standard Class | O2: United States | P2: Texas | Q2: Central | R2: Houston | S2: 0.2 | T2: 16.448 | U2: 5.5512 | V2: =IFERROR(Table12[[#This Row],[Profit]]/Table12[[#This Row],[Sales]],0) -> 0.3375
A3: 2 | B3: CA-2014-112326 | C3: 41643 | D3: =MONTH(Table12[[#This Row],[Order Date]]) -> 1 | E3: OFF-LA-10003223 | F3: Avery 508 | G3: Office Supplies | H3: Labels | I3: PO-19195 | J3: Home Office | K3: 3 | L3: 41647 | M3: =Table12[[#This Row],[Ship Date]]-Table12[[#This Row],[Order Date]] -> 4 | N3: Standard Class | O3: United States | P3: Illinois | Q3: Central | R3: Naperville | S3: 0.2 | T3: 11.784 | U3: 4.2717 | V3: =IFERROR(Table12[[#This Row],[Profit]]/Table12[[#This Row],[Sales]],0) -> 0.3625
A4: 3 | B4: CA-2014-112326 | C4: 41643 | D4: =MONTH(Table12[[#This Row],[Order Date]]) -> 1 | E4: OFF-ST-10002743 | F4: SAFCO Boltless Steel Shelving | G4: Office Supplies | H4: Storage | I4: PO-19195 | J4: Home Office | K4: 3 | L4: 41647 | M4: =Table12[[#This Row],[Ship Date]]-Table12[[#This Row],[Order Date]] -> 4 | N4: Standard Class | O4: United States | P4: Illinois | Q4: Central | R4: Naperville | S4: 0.2 | T4: 272.736 | U4: -64.7748 | V4: =IFERROR(Table12[[#This Row],[Profit]]/Table12[[#This Row],[Sales]],0) -> -0.2375
A5: 4 | B5: CA-2014-112326 | C5: 41643 | D5: =MONTH(Table12[[#This Row],[Order Date]]) -> 1 | E5: OFF-BI-10004094 | F5: GBC Standard Plastic Binding Systems Combs | G5: Office Supplies | H5: Binders | I5: PO-19195 | J5: Home Office | K5: 2 | L5: 41647 | M5: =Table12[[#This Row],[Ship Date]]-Table12[[#This Row],[Order Date]] -> 4 | N5: Standard Class | O5: United States | P5: Illinois | Q5: Central | R5: Naperville | S5: 0.8 | T5: 3.54 | U5: -5.487 | V5: =IFERROR(Table12[[#This Row],[Profit]]/Table12[[#This Row],[Sales]],0) -> -1.55
A6: 5 | B6: CA-2014-141817 | C6: 41644 | D6: =MONTH(Table12[[#This Row],[Order Date]]) -> 1 | E6: OFF-AR-10003478 | F6: Avery Hi-Liter EverBold Pen Style Fluorescent Highlighters, 4/Pack | G6: Office Supplies | H6: Art | I6: MB-18085 | J6: Consumer | K6: 3 | L6: 41651 | M6: =Table12[[#This Row],[Ship Date]]-Table12[[#This Row],[Order Date]] -> 7 | N6: Standard Class | O6: United States | P6: Pennsylvania | Q6: East | R6: Philadelphia | S6: 0.2 | T6: 19.536 | U6: 4.884 | V6: =IFERROR(Table12[[#This Row],[Profit]]/Table12[[#This Row],[Sales]],0) -> 0.25
A7: 6 | B7: CA-2014-130813 | C7: 41645 | D7: =MONTH(Table12[[#This Row],[Order Date]]) -> 1 | E7: OFF-PA-10002005 | F7: Xerox 225 | G7: Office Supplies | H7: Paper | I7: LS-17230 | J7: Consumer | K7: 3 | L7: 41647 | M7: =Table12[[#This Row],[Ship Date]]-Table12[[#This Row],[Order Date]] -> 2 | N7: Second Class | O7: United States | P7: California | Q7: West | R7: Los Angeles | S7: 0 | T7: 19.44 | U7: 9.3312 | V7: =IFERROR(Table12[[#This Row],[Profit]]/Table12[[#This Row],[Sales]],0) -> 0.48
A8: 7 | B8: CA-2014-106054 | C8: 41645 | D8: =MONTH(Table12[[#This Row],[Order Date]]) -> 1 | E8: OFF-AR-10002399 | F8: Dixon Prang Watercolor Pencils, 10-Color Set with Brush | G8: Office Supplies | H8: Art | I8: JO-15145 | J8: Corporate | K8: 3 | L8: 41646 | M8: =Table12[[#This Row],[Ship Date]]-Table12[[#This Row],[Order Date]] -> 1 | N8: First Class | O8: United States | P8: Georgia | Q8: South | R8: Athens | S8: 0 | T8: 12.78 | U8: 5.2398 | V8: =IFERROR(Table12[[#This Row],[Profit]]/Table12[[#This Row],[Sales]],0) -> 0.41
A9: 8 | B9: CA-2014-167199 | C9: 41645 | D9: =MONTH(Table12[[#This Row],[Order Date]]) -> 1 | E9: FUR-CH-10004063 | F9: Global Deluxe High-Back Manager's Chair | G9: Furniture | H9: Chairs | I9: ME-17320 | J9: Home Office | K9: 9 | L9: 41649 | M9: =Table12[[#This Row],[Ship Date]]-Table12[[#This Row],[Order Date]] -> 4 | N9: Standard Class | O9: United States | P9: Kentucky | Q9: South | R9: Henderson | S9: 0 | T9: 2573.82 | U9: 746.4078 | V9: =IFERROR(Table12[[#This Row],[Profit]]/Table12[[#This Row],[Sales]],0) -> 0.29
A10: 9 | B10: CA-2014-167199 | C10: 41645 | D10: =MONTH(Table12[[#This Row],[Order Date]]) -> 1 | E10: OFF-BI-10004632 | F10: Ibico Hi-Tech Manual Binding System | G10: Office Supplies | H10: Binders | I10: ME-17320 | J10: Home Office | K10: 2 | L10: 41649 | M10: =Table12[[#This Row],[Ship Date]]-Table12[[#This Row],[Order Date]] -> 4 | N10: Standard Class | O10: United States | P10: Kentucky | Q10: South | R10: Henderson | S10: 0 | T10: 609.98 | U10: 274.491 | V10: =IFERROR(Table12[[#This Row],[Profit]]/Table12[[#This Row],[Sales]],0) -> 0.45
A11: 10 | B11: CA-2014-167199 | C11: 41645 | D11: =MONTH(Table12[[#This Row],[Order Date]]) -> 1 | E11: OFF-AR-10001662 | F11: Rogers Handheld Barrel Pencil Sharpener | G11: Office Supplies | H11: Art | I11: ME-17320 | J11: Home Office | K11: 2 | L11: 41649 | M11: =Table12[[#This Row],[Ship Date]]-Table12[[#This Row],[Order Date]] -> 4 | N11: Standard Class | O11: United States | P11: Kentucky | Q11: South | R11: Henderson | S11: 0 | T11: 5.48 | U11: 1.4796 | V11: =IFERROR(Table12[[#This Row],[Profit]]/Table12[[#This Row],[Sales]],0) -> 0.27
A12: 11 | B12: CA-2014-167199 | C12: 41645 | D12: =MONTH(Table12[[#This Row],[Order Date]]) -> 1 | E12: TEC-PH-10004977 | F12: GE 30524EE4 | G12: Technology | H12: Phones | I12: ME-17320 | J12: Home Office | K12: 2 | L12: 41649 | M12: =Table12[[#This Row],[Ship Date]]-Table12[[#This Row],[Order Date]] -> 4 | N12: Standard Class | O12: United States | P12: Kentucky | Q12: South | R12: Henderson | S12: 0 | T12: 391.98 | U12: 113.6742 | V12: =IFERROR(Table12[[#This Row],[Profit]]/Table12[[#This Row],[Sales]],0) -> 0.29
A13: 12 | B13: CA-2014-167199 | C13: 41645 | D13: =MONTH(Table12[[#This Row],[Order Date]]) -> 1 | E13: TEC-PH-10004539 | F13: Wireless Extenders zBoost YX545 SOHO Signal Booster | G13: Technology | H13: Phones | I13: ME-17320 | J13: Home Office | K13: 4 | L13: 41649 | M13: =Table12[[#This Row],[Ship Date]]-Table12[[#This Row],[Order Date]] -> 4 | N13: Standard Class | O13: United States | P13: Kentucky | Q13: South | R13: Henderson | S13: 0 | T13: 755.96 | U13: 204.1092 | V13: =IFERROR(Table12[[#This Row],[Profit]]/Table12[[#This Row],[Sales]],0) -> 0.27
... A1993: 1992 | B1993: CA-2014-157644 | C1993: 42004 | D1993: =MONTH(Table12[[#This Row],[Order Date]]) -> 12 | E1993: OFF-LA-10003148 | F1993: Avery 51 | G1993: Office Supplies | H1993: Labels | I1993: AH-10030 | J1993: Corporate | K1993: 3 | L1993: 42005 | M1993: =Table12[[#This Row],[Ship Date]]-Table12[[#This Row],[Order Date]] -> 1 | N1993: First Class | O1993: United States | P1993: New York | Q1993: East | R1993: New York City | S1993: 0 | T1993: 18.9 | U1993: 8.694 | V1993: =IFERROR(Table12[[#This Row],[Profit]]/Table12[[#This Row],[Sales]],0) -> 0.46

Sheet 2015_Clean_Data_Analysis
A1: Row ID | B1: Order ID | C1: Order Date | D1: Month Number | E1: Product ID | F1: Product Name | G1: Category | H1: Sub-Category | I1: Customer ID | J1: Segment | K1: Quantity | L1: Ship Date | M1: Shipping Days | N1: Ship Mode | O1: Country | P1: State | Q1: Region | R1: City | S1: Discount | T1: Sales | U1: Profit | V1: Profit Margin
A2: 1 | B2: CA-2015-146262 | C2: 42006 | D2: =MONTH(Table11[[#This Row],[Order Date]]) -> 1 | E2: OFF-LA-10004544 | F2: Avery 505 | G2: Office Supplies | H2: Labels | I2: VW-21775 | J2: Corporate | K2: 2 | L2: 42013 | M2: =Table11[[#This Row],[Ship Date]]-Table11[[#This Row],[Order Date]] -> 7 | N2: Standard Class | O2: United States | P2: Ohio | Q2: East | R2: Medina | S2: 0.2 | T2: 23.68 | U2: 8.88 | V2: =Table11[[#This Row],[Profit]]/Table11[[#This Row],[Sales]] -> 0.375
A3: 2 | B3: CA-2015-146262 | C3: 42006 | D3: =MONTH(Table11[[#This Row],[Order Date]]) -> 1 | E3: FUR-BO-10004695 | F3: O'Sullivan 2-Door Barrister Bookcase in Odessa Pine | G3: Furniture | H3: Bookcases | I3: VW-21775 | J3: Corporate | K3: 5 | L3: 42013 | M3: =Table11[[#This Row],[Ship Date]]-Table11[[#This Row],[Order Date]] -> 7 | N3: Standard Class | O3: United States | P3: Ohio | Q3: East | R3: Medina | S3: 0.5 | T3: 452.45 | U3: -244.323 | V3: =Table11[[#This Row],[Profit]]/Table11[[#This Row],[Sales]] -> -0.54
A4: 3 | B4: CA-2015-146262 | C4: 42006 | D4: =MONTH(Table11[[#This Row],[Order Date]]) -> 1 | E4: TEC-PH-10002844 | F4: Speck Products Candyshell Flip Case | G4: Technology | H4: Phones | I4: VW-21775 | J4: Corporate | K4: 3 | L4: 42013 | M4: =Table11[[#This Row],[Ship Date]]-Table11[[#This Row],[Order Date]] -> 7 | N4: Standard Class | O4: United States | P4: Ohio | Q4: East | R4: Medina | S4: 0.4 | T4: 62.982 | U4: -14.6958 | V4: =Table11[[#This Row],[Profit]]/Table11[[#This Row],[Sales]] -> -0.23333333
A5: 4 | B5: CA-2015-146262 | C5: 42006 | D5: =MONTH(Table11[[#This Row],[Order Date]]) -> 1 | E5: TEC-MA-10000864 | F5: Cisco 9971 IP Video Phone Charcoal | G5: Technology | H5: Machines | I5: VW-21775 | J5: Corporate | K5: 9 | L5: 42013 | M5: =Table11[[#This Row],[Ship Date]]-Table11[[#This Row],[Order Date]] -> 7 | N5: Standard Class | O5: United States | P5: Ohio | Q5: East | R5: Medina | S5: 0.7 | T5: 1188 | U5: -950.4 | V5: =Table11[[#This Row],[Profit]]/Table11[[#This Row],[Sales]] -> -0.8
A6: 5 | B6: CA-2015-146262 | C6: 42006 | D6: =MONTH(Table11[[#This Row],[Order Date]]) -> 1 | E6: TEC-AC-10000109 | F6: Sony Micro Vault Click 16 GB USB 2.0 Flash Drive | G6: Technology | H6: Accessories | I6: VW-21775 | J6: Corporate | K6: 2 | L6: 42013 | M6: =Table11[[#This Row],[Ship Date]]-Table11[[#This Row],[Order Date]] -> 7 | N6: Standard Class | O6: United States | P6: Ohio | Q6: East | R6: Medina | S6: 0.2 | T6: 89.584 | U6: 4.4792 | V6: =Table11[[#This Row],[Profit]]/Table11[[#This Row],[Sales]] -> 0.05
A7: 6 | B7: CA-2015-104514 | C7: 42006 | D7: =MONTH(Table11[[#This Row],[Order Date]]) -> 1 | E7: OFF-ST-10001837 | F7: SAFCO Mobile Desk Side File, Wire Frame | G7: Office Supplies | H7: Storage | I7: CB-12535 | J7: Corporate | K7: 2 | L7: 42008 | M7: =Table11[[#This Row],[Ship Date]]-Table11[[#This Row],[Order Date]] -> 2 | N7: Second Class | O7: United States | P7: Delaware | Q7: East | R7: Newark | S7: 0 | T7: 85.52 | U7: 22.2352 | V7: =Table11[[#This Row],[Profit]]/Table11[[#This Row],[Sales]] -> 0.26
A8: 7 | B8: CA-2015-104514 | C8: 42006 | D8: =MONTH(Table11[[#This Row],[Order Date]]) -> 1 | E8: OFF-AR-10001473 | F8: Newell 313 | G8: Office Supplies | H8: Art | I8: CB-12535 | J8: Corporate | K8: 3 | L8: 42008 | M8: =Table11[[#This Row],[Ship Date]]-Table11[[#This Row],[Order Date]] -> 2 | N8: Second Class | O8: United States | P8: Delaware | Q8: East | R8: Newark | S8: 0 | T8: 9.84 | U8: 2.6568 | V8: =Table11[[#This Row],[Profit]]/Table11[[#This Row],[Sales]] -> 0.27
A9: 8 | B9: CA-2015-104514 | C9: 42006 | D9: =MONTH(Table11[[#This Row],[Order Date]]) -> 1 | E9: OFF-PA-10004285 | F9: Xerox 1959 | G9: Office Supplies | H9: Paper | I9: CB-12535 | J9: Corporate | K9: 3 | L9: 42008 | M9: =Table11[[#This Row],[Ship Date]]-Table11[[#This Row],[Order Date]] -> 2 | N9: Second Class | O9: United States | P9: Delaware | Q9: East | R9: Newark | S9: 0 | T9: 20.04 | U9: 9.6192 | V9: =Table11[[#This Row],[Profit]]/Table11[[#This Row],[Sales]] -> 0.48
A10: 9 | B10: CA-2015-121097 | C10: 42007 | D10: =MONTH(Table11[[#This Row],[Order Date]]) -> 1 | E10: OFF-PA-10001937 | F10: Xerox 21 | G10: Office Supplies | H10: Paper | I10: SF-20965 | J10: Corporate | K10: 2 | L10: 42012 | M10: =Table11[[#This Row],[Ship Date]]-Table11[[#This Row],[Order Date]] -> 5 | N10: Standard Class | O10: United States | P10: Texas | Q10: Central | R10: Baytown | S10: 0.2 | T10: 10.368 | U10: 3.6288 | V10: =Table11[[#This Row],[Profit]]/Table11[[#This Row],[Sales]] -> 0.35
A11: 10 | B11: CA-2015-141243 | C11: 42007 | D11: =MONTH(Table11[[#This Row],[Order Date]]) -> 1 | E11: TEC-AC-10003198 | F11: Enermax Acrylux Wireless Keyboard | G11: Technology | H11: Accessories | I11: AH-10465 | J11: Consumer | K11: 5 | L11: 42012 | M11: =Table11[[#This Row],[Ship Date]]-Table11[[#This Row],[Order Date]] -> 5 | N11: Second Class | O11: United States | P11: Texas | Q11: Central | R11: Dallas | S11: 0.2 | T11: 398.4 | U11: 84.66 | V11: =Table11[[#This Row],[Profit]]/Table11[[#This Row],[Sales]] -> 0.2125
A12: 11 | B12: CA-2015-141243 | C12: 42007 | D12: =MONTH(Table11[[#This Row],[Order Date]]) -> 1 | E12: OFF-AR-10001246 | F12: Newell 317 | G12: Office Supplies | H12: Art | I12: AH-10465 | J12: Consumer | K12: 3 | L12: 42012 | M12: =Table11[[#This Row],[Ship Date]]-Table11[[#This Row],[Order Date]] -> 5 | N12: Second Class | O12: United States | P12: Texas | Q12: Central | R12: Dallas | S12: 0.2 | T12: 7.056 | U12: 0.7938 | V12: =Table11[[#This Row],[Profit]]/Table11[[#This Row],[Sales]] -> 0.1125
A13: 12 | B13: CA-2015-141243 | C13: 42007 | D13: =MONTH(Table11[[#This Row],[Order Date]]) -> 1 | E13: FUR-BO-10003272 | F13: O'Sullivan Living Dimensions 5-Shelf Bookcases | G13: Furniture | H13: Bookcases | I13: AH-10465 | J13: Consumer | K13: 9 | L13: 42012 | M13: =Table11[[#This Row],[Ship Date]]-Table11[[#This Row],[Order Date]] -> 5 | N13: Second Class | O13: United States | P13: Texas | Q13: Central | R13: Dallas | S13: 0.32 | T13: 1352.3976 | U13: -437.5404 | V13: =Table11[[#This Row],[Profit]]/Table11[[#This Row],[Sales]] -> -0.32352941
... A2103: 2102 | B2103: CA-2015-139780 | C2103: 42369 | D2103: =MONTH(Table11[[#This Row],[Order Date]]) -> 12 | E2103: OFF-BI-10004139 | F2103: Fellowes Presentation Covers for Comb Binding Machines | G2103: Office Supplies | H2103: Binders | I2103: AH-10690 | J2103: Corporate | K2103: 8 | L2103: 42371 | M2103: =Table11[[#This Row],[Ship Date]]-Table11[[#This Row],[Order Date]] -> 2 | N2103: Second Class | O2103: United States | P2103: Michigan | Q2103: Central | R2103: Detroit | S2103: 0 | T2103: 116.4 | U2103: 52.38 | V2103: =Table11[[#This Row],[Profit]]/Table11[[#This Row],[Sales]] -> 0.45

Sheet 2016_Clean_Data_Analysis
A1: Row ID | B1: Order ID | C1: Order Date | D1: Month Number | E1: Product ID | F1: Product Name | G1: Category | H1: Sub-Category | I1: Customer ID | J1: Segment | K1: Quantity | L1: Ship Date | M1: Shipping Days | N1: Ship Mode | O1: Country | P1: State | Q1: Region | R1: City | S1: Discount | T1: Sales | U1: Profit | V1: Profit Margin
A2: 1 | B2: CA-2016-160304 | C2: 42371 | D2: =MONTH(Table10[[#This Row],[Order Date]]) -> 1 | E2: FUR-BO-10004709 | F2: Bush Westfield Collection Bookcases, Medium Cherry Finish | G2: Furniture | H2: Bookcases | I2: BM-11575 | J2: Corporate | K2: 3 | L2: 42376 | M2: =Table10[[#This Row],[Ship Date]]-Table10[[#This Row],[Order Date]] -> 5 | N2: Standard Class | O2: United States | P2: Maryland | Q2: East | R2: Gaithersburg | S2: 0 | T2: 173.94 | U2: 38.2668 | V2: =Table10[[#This Row],[Profit]]/Table10[[#This Row],[Sales]] -> 0.22
A3: 2 | B3: CA-2016-160304 | C3: 42371 | D3: =MONTH(Table10[[#This Row],[Order Date]]) -> 1 | E3: TEC-PH-10000455 | F3: GE 30522EE2 | G3: Technology | H3: Phones | I3: BM-11575 | J3: Corporate | K3: 2 | L3: 42376 | M3: =Table10[[#This Row],[Ship Date]]-Table10[[#This Row],[Order Date]] -> 5 | N3: Standard Class | O3: United States | P3: Maryland | Q3: East | R3: Gaithersburg | S3: 0 | T3: 231.98 | U3: 67.2742 | V3: =Table10[[#This Row],[Profit]]/Table10[[#This Row],[Sales]] -> 0.29
A4: 3 | B4: CA-2016-125206 | C4: 42372 | D4: =MONTH(Table10[[#This Row],[Order Date]]) -> 1 | E4: OFF-ST-10003692 | F4: Recycled Steel Personal File for Hanging File Folders | G4: Office Supplies | H4: Storage | I4: LR-16915 | J4: Consumer | K4: 2 | L4: 42374 | M4: =Table10[[#This Row],[Ship Date]]-Table10[[#This Row],[Order Date]] -> 2 | N4: First Class | O4: United States | P4: California | Q4: West | R4: Los Angeles | S4: 0 | T4: 114.46 | U4: 28.615 | V4: =Table10[[#This Row],[Profit]]/Table10[[#This Row],[Sales]] -> 0.25
A5: 4 | B5: US-2016-116365 | C5: 42372 | D5: =MONTH(Table10[[#This Row],[Order Date]]) -> 1 | E5: TEC-AC-10002217 | F5: Imation¬†Clip USB¬†flash drive¬†- 8 GB | G5: Technology | H5: Accessories | I5: CA-12310 | J5: Corporate | K5: 2 | L5: 42377 | M5: =Table10[[#This Row],[Ship Date]]-Table10[[#This Row],[Order Date]] -> 5 | N5: Standard Class | O5: United States | P5: Texas | Q5: Central | R5: San Antonio | S5: 0.2 | T5: 30.08 | U5: -5.264 | V5: =Table10[[#This Row],[Profit]]/Table10[[#This Row],[Sales]] -> -0.175
A6: 5 | B6: US-2016-116365 | C6: 42372 | D6: =MONTH(Table10[[#This Row],[Order Date]]) -> 1 | E6: TEC-AC-10002942 | F6: WD My Passport Ultra 1TB Portable External Hard Drive | G6: Technology | H6: Accessories | I6: CA-12310 | J6: Corporate | K6: 3 | L6: 42377 | M6: =Table10[[#This Row],[Ship Date]]-Table10[[#This Row],[Order Date]] -> 5 | N6: Standard Class | O6: United States | P6: Texas | Q6: Central | R6: San Antonio | S6: 0.2 | T6: 165.6 | U6: -6.21 | V6: =Table10[[#This Row],[Profit]]/Table10[[#This Row],[Sales]] -> -0.0375
A7: 6 | B7: US-2016-116365 | C7: 42372 | D7: =MONTH(Table10[[#This Row],[Order Date]]) -> 1 | E7: TEC-PH-10002890 | F7: AT&T 17929 Lendline Telephone | G7: Technology | H7: Phones | I7: CA-12310 | J7: Corporate | K7: 5 | L7: 42377 | M7: =Table10[[#This Row],[Ship Date]]-Table10[[#This Row],[Order Date]] -> 5 | N7: Standard Class | O7: United States | P7: Texas | Q7: Central | R7: San Antonio | S7: 0.2 | T7: 180.96 | U7: 13.572 | V7: =Table10[[#This Row],[Profit]]/Table10[[#This Row],[Sales]] -> 0.075
A8: 7 | B8: CA-2016-105207 | C8: 42372 | D8: =MONTH(Table10[[#This Row],[Order Date]]) -> 1 | E8: FUR-TA-10000617 | F8: Hon Practical Foundations 30 x 60 Training Table, Light Gray/Charcoal | G8: Furniture | H8: Tables | I8: BO-11350 | J8: Corporate | K8: 7 | L8: 42377 | M8: =Table10[[#This Row],[Ship Date]]-Table10[[#This Row],[Order Date]] -> 5 | N8: Standard Class | O8: United States | P8: Oklahoma | Q8: Central | R8: Broken Arrow | S8: 0 | T8: 1592.85 | U8: 350.427 | V8: =Table10[[#This Row],[Profit]]/Table10[[#This Row],[Sales]] -> 0.22
A9: 8 | B9: CA-2016-105207 | C9: 42372 | D9: =MONTH(Table10[[#This Row],[Order Date]]) -> 1 | E9: OFF-BI-10004364 | F9: Storex Dura Pro Binders | G9: Office Supplies | H9: Binders | I9: BO-11350 | J9: Corporate | K9: 2 | L9: 42377 | M9: =Table10[[#This Row],[Ship Date]]-Table10[[#This Row],[Order Date]] -> 5 | N9: Standard Class | O9: United States | P9: Oklahoma | Q9: Central | R9: Broken Arrow | S9: 0 | T9: 11.88 | U9: 5.346 | V9: =Table10[[#This Row],[Profit]]/Table10[[#This Row],[Sales]] -> 0.45
A10: 9 | B10: US-2016-164630 | C10: 42373 | D10: =MONTH(Table10[[#This Row],[Order Date]]) -> 1 | E10: TEC-CO-10000971 | F10: Hewlett Packard 310 Color Digital Copier | G10: Technology | H10: Copiers | I10: EB-13975 | J10: Corporate | K10: 4 | L10: 42378 | M10: =Table10[[#This Row],[Ship Date]]-Table10[[#This Row],[Order Date]] -> 5 | N10: Standard Class | O10: United States | P10: North Carolina | Q10: South | R10: Charlotte | S10: 0.2 | T10: 959.968 | U10: 119.996 | V10: =Table10[[#This Row],[Profit]]/Table10[[#This Row],[Sales]] -> 0.125
A11: 10 | B11: CA-2016-158211 | C11: 42373 | D11: =MONTH(Table10[[#This Row],[Order Date]]) -> 1 | E11: OFF-AR-10004078 | F11: Newell 312 | G11: Office Supplies | H11: Art | I11: BP-11185 | J11: Corporate | K11: 1 | L11: 42377 | M11: =Table10[[#This Row],[Ship Date]]-Table10[[#This Row],[Order Date]] -> 4 | N11: Standard Class | O11: United States | P11: Pennsylvania | Q11: East | R11: Philadelphia | S11: 0.2 | T11: 4.672 | U11: 0.584 | V11: =Table10[[#This Row],[Profit]]/Table10[[#This Row],[Sales]] -> 0.125
A12: 11 | B12: CA-2016-158211 | C12: 42373 | D12: =MONTH(Table10[[#This Row],[Order Date]]) -> 1 | E12: OFF-BI-10002026 | F12: Avery Arch Ring Binders | G12: Office Supplies | H12: Binders | I12: BP-11185 | J12: Corporate | K12: 6 | L12: 42377 | M12: =Table10[[#This Row],[Ship Date]]-Table10[[#This Row],[Order Date]] -> 4 | N12: Standard Class | O12: United States | P12: Pennsylvania | Q12: East | R12: Philadelphia | S12: 0.7 | T12: 104.58 | U12: -80.178 | V12: =Table10[[#This Row],[Profit]]/Table10[[#This Row],[Sales]] -> -0.76666667
A13: 12 | B13: CA-2016-134474 | C13: 42374 | D13: =MONTH(Table10[[#This Row],[Order Date]]) -> 1 | E13: TEC-AC-10001714 | F13: Logitech¬†MX Performance Wireless Mouse | G13: Technology | H13: Accessories | I13: AJ-10795 | J13: Corporate | K13: 6 | L13: 42376 | M13: =Table10[[#This Row],[Ship Date]]-Table10[[#This Row],[Order Date]] -> 2 | N13: Second Class | O13: United States | P13: Florida | Q13: South | R13: Jacksonville | S13: 0.2 | T13: 191.472 | U13: 40.6878 | V13: =Table10[[#This Row],[Profit]]/Table10[[#This Row],[Sales]] -> 0.2125
... A2588: 2587 | B2588: US-2017-105830 | C2588: 42735 | D2588: =MONTH(Table10[[#This Row],[Order Date]]) -> 12 | E2588: OFF-ST-10002554 | F2588: Tennsco Industrial Shelving | G2588: Office Supplies | H2588: Storage | I2588: DB-13660 | J2588: Consumer | K2588: 4 | L2588: 42737 | M2588: =Table10[[#This Row],[Ship Date]]-Table10[[#This Row],[Order Date]] -> 2 | N2588: First Class | O2588: United States | P2588: Ohio | Q2588: East | R2588: Lancaster | S2588: 0.2 | T2588: 156.512 | U2588: -35.2152 | V2588: =Table10[[#This Row],[Profit]]/Table10[[#This Row],[Sales]] -> -0.225

Sheet 2017_Clean_Data_Analysis
A1: Row ID | B1: Order ID | C1: Order Date | D1: Month Number | E1: Product ID | F1: Product Name | G1: Category | H1: Sub-Category | I1: Customer ID | J1: Segment | K1: Quantity | L1: Ship Date | M1: Shipping Days | N1: Ship Mode | O1: Country | P1: State | Q1: Region | R1: City | S1: Discount | T1: Sales | U1: Profit | V1: Profit Margin
A2: 1 | B2: CA-2017-107503 | C2: 42736 | D2: =MONTH(Table3[[#This Row],[Order Date]]) -> 1 | E2: FUR-FU-10003878 | F2: Linden 10" Round Wall Clock, Black | G2: Furniture | H2: Furnishings | I2: GA-14725 | J2: Consumer | K2: 4 | L2: 42741 | M2: =Table3[[#This Row],[Ship Date]]-Table3[[#This Row],[Order Date]] -> 5 | N2: Standard Class | O2: United States | P2: Ohio | Q2: East | R2: Lorain | S2: 0.2 | T2: 48.896 | U2: 8.5568 | V2: =Table3[[#This Row],[Profit]]/Table3[[#This Row],[Sales]] -> 0.175
A3: 2 | B3: CA-2017-144463 | C3: 42736 | D3: =MONTH(Table3[[#This Row],[Order Date]]) -> 1 | E3: FUR-FU-10001215 | F3: Howard Miller 11-1/2" Diameter Brentwood Wall Clock | G3: Furniture | H3: Furnishings | I3: SC-20725 | J3: Consumer | K3: 11 | L3: 42740 | M3: =Table3[[#This Row],[Ship Date]]-Table3[[#This Row],[Order Date]] -> 4 | N3: Standard Class | O3: United States | P3: California | Q3: West | R3: Los Angeles | S3: 0 | T3: 474.43 | U3: 199.2606 | V3: =Table3[[#This Row],[Profit]]/Table3[[#This Row],[Sales]] -> 0.42
A4: 3 | B4: CA-2017-154466 | C4: 42736 | D4: =MONTH(Table3[[#This Row],[Order Date]]) -> 1 | E4: OFF-BI-10002012 | F4: Wilson Jones Easy Flow II Sheet Lifters | G4: Office Supplies | H4: Binders | I4: DP-13390 | J4: Home Office | K4: 2 | L4: 42737 | M4: =Table3[[#This Row],[Ship Date]]-Table3[[#This Row],[Order Date]] -> 1 | N4: First Class | O4: United States | P4: Wisconsin | Q4: Central | R4: Franklin | S4: 0 | T4: 3.6 | U4: 1.728 | V4: =Table3[[#This Row],[Profit]]/Table3[[#This Row],[Sales]] -> 0.48
A5: 4 | B5: CA-2017-151750 | C5: 42736 | D5: =MONTH(Table3[[#This Row],[Order Date]]) -> 1 | E5: OFF-ST-10002743 | F5: SAFCO Boltless Steel Shelving | G5: Office Supplies | H5: Storage | I5: JM-15250 | J5: Consumer | K5: 5 | L5: 42740 | M5: =Table3[[#This Row],[Ship Date]]-Table3[[#This Row],[Order Date]] -> 4 | N5: Standard Class | O5: United States | P5: Texas | Q5: Central | R5: Huntsville | S5: 0.2 | T5: 454.56 | U5: -107.958 | V5: =Table3[[#This Row],[Profit]]/Table3[[#This Row],[Sales]] -> -0.2375
A6: 5 | B6: CA-2017-151750 | C6: 42736 | D6: =MONTH(Table3[[#This Row],[Order Date]]) -> 1 | E6: FUR-FU-10002116 | F6: Tenex Carpeted, Granite-Look or Clear Contemporary Contour Shape Chair Mats | G6: Furniture | H6: Furnishings | I6: JM-15250 | J6: Consumer | K6: 5 | L6: 42740 | M6: =Table3[[#This Row],[Ship Date]]-Table3[[#This Row],[Order Date]] -> 4 | N6: Standard Class | O6: United States | P6: Texas | Q6: Central | R6: Huntsville | S6: 0.6 | T6: 141.42 | U6: -187.3815 | V6: =Table3[[#This Row],[Profit]]/Table3[[#This Row],[Sales]] -> -1.325
A7: 6 | B7: CA-2017-151750 | C7: 42736 | D7: =MONTH(Table3[[#This Row],[Order Date]]) -> 1 | E7: FUR-CH-10003199 | F7: Office Star - Contemporary Task Swivel Chair | G7: Furniture | H7: Chairs | I7: JM-15250 | J7: Consumer | K7: 4 | L7: 42740 | M7: =Table3[[#This Row],[Ship Date]]-Table3[[#This Row],[Order Date]] -> 4 | N7: Standard Class | O7: United States | P7: Texas | Q7: Central | R7: Huntsville | S7: 0.3 | T7: 310.744 | U7: -26.6352 | V7: =Table3[[#This Row],[Profit]]/Table3[[#This Row],[Sales]] -> -0.085714286
A8: 7 | B8: CA-2017-151750 | C8: 42736 | D8: =MONTH(Table3[[#This Row],[Order Date]]) -> 1 | E8: OFF-AR-10003158 | F8: Fluorescent Highlighters by Dixon | G8: Office Supplies | H8: Art | I8: JM-15250 | J8: Consumer | K8: 4 | L8: 42740 | M8: =Table3[[#This Row],[Ship Date]]-Table3[[#This Row],[Order Date]] -> 4 | N8: Standard Class | O8: United States | P8: Texas | Q8: Central | R8: Huntsville | S8: 0.2 | T8: 12.736 | U8: 2.2288 | V8: =Table3[[#This Row],[Profit]]/Table3[[#This Row],[Sales]] -> 0.175
A9: 8 | B9: CA-2017-151750 | C9: 42736 | D9: =MONTH(Table3[[#This Row],[Order Date]]) -> 1 | E9: OFF-BI-10000301 | F9: GBC Instant Report Kit | G9: Office Supplies | H9: Binders | I9: JM-15250 | J9: Consumer | K9: 5 | L9: 42740 | M9: =Table3[[#This Row],[Ship Date]]-Table3[[#This Row],[Order Date]] -> 4 | N9: Standard Class | O9: United States | P9: Texas | Q9: Central | R9: Huntsville | S9: 0.8 | T9: 6.47 | U9: -9.705 | V9: =Table3[[#This Row],[Profit]]/Table3[[#This Row],[Sales]] -> -1.5
A10: 9 | B10: CA-2017-151750 | C10: 42736 | D10: =MONTH(Table3[[#This Row],[Order Date]]) -> 1 | E10: OFF-BI-10000343 | F10: Pressboard Covers with Storage Hooks, 9 1/2" x 11", Light Blue | G10: Office Supplies | H10: Binders | I10: JM-15250 | J10: Consumer | K10: 14 | L10: 42740 | M10: =Table3[[#This Row],[Ship Date]]-Table3[[#This Row],[Order Date]] -> 4 | N10: Standard Class | O10: United States | P10: Texas | Q10: Central | R10: Huntsville | S10: 0.8 | T10: 13.748 | U10: -22.6842 | V10: =Table3[[#This Row],[Profit]]/Table3[[#This Row],[Sales]] -> -1.65
A11: 10 | B11: CA-2017-151750 | C11: 42736 | D11: =MONTH(Table3[[#This Row],[Order Date]]) -> 1 | E11: OFF-AP-10004708 | F11: Fellowes Superior 10 Outlet Split Surge Protector | G11: Office Supplies | H11: Appliances | I11: JM-15250 | J11: Consumer | K11: 2 | L11: 42740 | M11: =Table3[[#This Row],[Ship Date]]-Table3[[#This Row],[Order Date]] -> 4 | N11: Standard Class | O11: United States | P11: Texas | Q11: Central | R11: Huntsville | S11: 0.8 | T11: 15.224 | U11: -38.8212 | V11: =Table3[[#This Row],[Profit]]/Table3[[#This Row],[Sales]] -> -2.55
A12: 11 | B12: CA-2017-113481 | C12: 42737 | D12: =MONTH(Table3[[#This Row],[Order Date]]) -> 1 | E12: TEC-MA-10002178 | F12: Cisco CP-7937G Unified IP Conference Station Phone | G12: Technology | H12: Machines | I12: AS-10045 | J12: Corporate | K12: 2 | L12: 42739 | M12: =Table3[[#This Row],[Ship Date]]-Table3[[#This Row],[Order Date]] -> 2 | N12: First Class | O12: United States | P12: North Carolina | Q12: South | R12: Jacksonville | S12: 0.5 | T12: 695.7 | U12: -27.828 | V12: =Table3[[#This Row],[Profit]]/Table3[[#This Row],[Sales]] -> -0.04
A13: 12 | B13: CA-2017-113481 | C13: 42737 | D13: =MONTH(Table3[[#This Row],[Order Date]]) -> 1 | E13: OFF-BI-10003694 | F13: Avery 3 1/2" Diskette Storage Pages, 10/Pack | G13: Office Supplies | H13: Binders | I13: AS-10045 | J13: Corporate | K13: 5 | L13: 42739 | M13: =Table3[[#This Row],[Ship Date]]-Table3[[#This Row],[Order Date]] -> 2 | N13: First Class | O13: United States | P13: North Carolina | Q13: South | R13: Jacksonville | S13: 0.7 | T13: 15.66 | U13: -12.528 | V13: =Table3[[#This Row],[Profit]]/Table3[[#This Row],[Sales]] -> -0.8
... A3313: 3312 | B3313: CA-2017-156720 | C3313: 43099 | D3313: =MONTH(Table3[[#This Row],[Order Date]]) -> 12 | E3313: OFF-FA-10003472 | F3313: Bagged Rubber Bands | G3313: Office Supplies | H3313: Fasteners | I3313: JM-15580 | J3313: Consumer | K3313: 3 | L3313: 43103 | M3313: =Table3[[#This Row],[Ship Date]]-Table3[[#This Row],[Order Date]] -> 4 | N3313: Standard Class | O3313: United States | P3313: Colorado | Q3313: West | R3313: Loveland | S3313: 0.2 | T3313: 3.024 | U3313: -0.6048 | V3313: =Table3[[#This Row],[Profit]]/Table3[[#This Row],[Sales]] -> -0.2

Sheet Analysis
A1: Data Issues | B1: 2014 | C1: 2015 | D1: 2016 | E1: 2017 | F1: Grand Total
A2: Missing Values | B2: =ISBLANK(Table12[[#This Row],[Month Number]]) -> FALSE | C2: =ISBLANK(Table12[[#This Row],[Month Number]]) -> FALSE | D2: =ISBLANK(Table12[[#This Row],[Month Number]]) -> FALSE | E2: =ISBLANK(Table12[[#This Row],[Month Number]]) -> FALSE
A3: Duplicate records | B3: 1 | C3: 0 | D3: 0 | E3: 0 | F3: =SUM(Table14[[#This Row],[2014]:[2017]]) -> 1
A4: Date Issues | B4: 0 | C4: 0 | D4: 0 | E4: 0 | F4: =SUM(Table14[[#This Row],[2014]:[2017]]) -> 0
A5: Negative Profits | B5: =COUNTIF('2014_Clean_Data_Analysis'!U1:U1993, "<0") -> 376 | C5: =COUNTIF('2015_Clean_Data_Analysis'!$U$1:$U$2102, "<0") -> 397 | D5: =COUNTIF('2016_Clean_Data_Analysis'!U1:U2588, "<0") -> 477 | E5: =COUNTIF('2017_Clean_Data_Analysis'!U1:U3313, "<0") -> 620 | F5: =SUM(Table14[[#This Row],[2014]:[2017]]) -> 1870
A6: Unusual Discounts | B6: =COUNTIF('2014_Clean_Data_Analysis'!S1:S1993, ">50%") -> 166 | C6: =COUNTIF('2015_Clean_Data_Analysis'!S1:S2103, ">50%") -> 187 | D6: =COUNTIF('2016_Clean_Data_Analysis'!S1:S2588, ">50%") -> 219 | E6: =COUNTIF('2017_Clean_Data_Analysis'!S1:S3313, ">50%") -> 284 | F6: =SUM(Table14[[#This Row],[2014]:[2017]]) -> 856
A7: Monthly Orders | B7: 2014 | C7: 2015 | D7: 2016 | E7: 2017 | F7: Grand Monthly Orders
A8: January | B8: =COUNTIF('2014_Clean_Data_Analysis'!D:D, 1) -> 79 | C8: =COUNTIF('2015_Clean_Data_Analysis'!D:D, 1) -> 58 | D8: =COUNTIF('2016_Clean_Data_Analysis'!D:D, 1) -> 89 | E8: =COUNTIF('2017_Clean_Data_Analysis'!D:D, 1) -> 155 | F8: =SUM(Analysis!$B8:$E8) -> 381
A9: February | B9: =COUNTIF('2014_Clean_Data_Analysis'!D:D, 2) -> 46 | C9: =COUNTIF('2015_Clean_Data_Analysis'!D:D, 2) -> 64 | D9: =COUNTIF('2016_Clean_Data_Analysis'!D:D, 2) -> 83 | E9: =COUNTIF('2017_Clean_Data_Analysis'!D:D, 2) -> 107 | F9: =SUM(Analysis!$B9:$E9) -> 300
A10: March | B10: =COUNTIF('2014_Clean_Data_Analysis'!D:D, 3) -> 157 | C10: =COUNTIF('2015_Clean_Data_Analysis'!D:D, 3) -> 138 | D10: =COUNTIF('2016_Clean_Data_Analysis'!D:D, 3) -> 163 | E10: =COUNTIF('2017_Clean_Data_Analysis'!D:D, 3) -> 238 | F10: =SUM(Analysis!$B10:$E10) -> 696
A11: April | B11: =COUNTIF('2014_Clean_Data_Analysis'!D:D, 4) -> 134 | C11: =COUNTIF('2015_Clean_Data_Analysis'!D:D, 4) -> 160 | D11: =COUNTIF('2016_Clean_Data_Analysis'!D:D, 4) -> 170 | E11: =COUNTIF('2017_Clean_Data_Analysis'!D:D, 4) -> 203 | F11: =SUM(Analysis!$B11:$E11) -> 667
A12: May | B12: =COUNTIF('2014_Clean_Data_Analysis'!D:D, 5) -> 122 | C12: =COUNTIF('2015_Clean_Data_Analysis'!D:D, 5) -> 146 | D12: =COUNTIF('2016_Clean_Data_Analysis'!D:D, 5) -> 225 | E12: =COUNTIF('2017_Clean_Data_Analysis'!D:D, 5) -> 242 | F12: =SUM(Analysis!$B12:$E12) -> 735
A13: June | B13: =COUNTIF('2014_Clean_Data_Analysis'!D:D, 6) -> 135 | C13: =COUNTIF('2015_Clean_Data_Analysis'!D:D, 6) -> 138 | D13: =COUNTIF('2016_Clean_Data_Analysis'!D:D, 6) -> 199 | E13: =COUNTIF('2017_Clean_Data_Analysis'!D:D, 6) -> 245 | F13: =SUM(Analysis!$B13:$E13) -> 717
A14: July | B14: =COUNTIF('2014_Clean_Data_Analysis'!D:D, 7) -> 143 | C14: =COUNTIF('2015_Clean_Data_Analysis'!D:D, 7) -> 140 | D14: =COUNTIF('2016_Clean_Data_Analysis'!D:D, 7) -> 201 | E14: =COUNTIF('2017_Clean_Data_Analysis'!D:D, 7) -> 226 | F14: =SUM(Analysis!$B14:$E14) -> 710
A15: August | B15: =COUNTIF('2014_Clean_Data_Analysis'!D:D, 8) -> 153 | C15: =COUNTIF('2015_Clean_Data_Analysis'!D:D, 8) -> 159 | D15: =COUNTIF('2016_Clean_Data_Analysis'!D:D, 8) -> 176 | E15: =COUNTIF('2017_Clean_Data_Analysis'!D:D, 8) -> 218 | F15: =SUM(Analysis!$B15:$E15) -> 706
A16: September | B16: =COUNTIF('2014_Clean_Data_Analysis'!D:D, 9) -> 268 | C16: =COUNTIF('2015_Clean_Data_Analysis'!D:D, 9) -> 293 | D16: =COUNTIF('2016_Clean_Data_Analysis'!D:D, 9) -> 363 | E16: =COUNTIF('2017_Clean_Data_Analysis'!D:D, 9) -> 459 | F16: =SUM(Analysis!$B16:$E16) -> 1383
A17: October | B17: =COUNTIF('2014_Clean_Data_Analysis'!D:D, 10) -> 159 | C17: =COUNTIF('2015_Clean_Data_Analysis'!D:D, 10) -> 166 | D17: =COUNTIF('2016_Clean_Data_Analysis'!D:D, 10) -> 196 | E17: =COUNTIF('2017_Clean_Data_Analysis'!D:D, 10) -> 298 | F17: =SUM(Analysis!$B17:$E17) -> 819
A18: November | B18: =COUNTIF('2014_Clean_Data_Analysis'!D:D, 11) -> 318 | C18: =COUNTIF('2015_Clean_Data_Analysis'!D:D, 11) -> 324 | D18: =COUNTIF('2016_Clean_Data_Analysis'!D:D, 11) -> 370 | E18: =COUNTIF('2017_Clean_Data_Analysis'!D:D, 11) -> 459 | F18: =SUM(Analysis!$B18:$E18) -> 1471
A19: December | B19: =COUNTIF('2014_Clean_Data_Analysis'!D:D, 12) -> 278 | C19: =COUNTIF('2015_Clean_Data_Analysis'!D:D, 12) -> 316 | D19: =COUNTIF('2016_Clean_Data_Analysis'!D:D, 12) -> 352 | E19: =COUNTIF('2017_Clean_Data_Analysis'!D:D, 12) -> 462 | F19: =SUM(Analysis!$B19:$E19) -> 1408
A20: Total Orders | B20: =SUM(B8:B19) -> 1992 | C20: =SUM(C8:C19) -> 2102 | D20: =SUM(D8:D19) -> 2587 | E20: =SUM(E8:E19) -> 3312 | F20: =SUM(F8:F19) -> 9993
A21: Monthly Sales | B21: 2014 | C21: 2015 | D21: 2016 | E21: 2017 | F21: Grand Sales
A22: January | B22: =SUMIF(Table12[Month Number], 1, Table12[Sales]) -> 14236.895 | C22: =SUMIF(Table11[Month Number], 1, Table11[Sales]) -> 18174.076 | D22: =SUMIF(Table10[Month Number], 1, Table10[Sales]) -> 18542.491 | E22: =SUMIF(Table3[Month Number], 1, Table3[Sales]) -> 43971.374 | F22: =SUM(Table2[[#This Row],[2014]:[2017]]) -> 94924.836
A23: February | B23: =SUMIF(Table12[Month Number], 2, Table12[Sales]) -> 4519.892 | C23: =SUMIF(Table11[Month Number], 2, Table11[Sales]) -> 11951.411 | D23: =SUMIF(Table10[Month Number], 2, Table10[Sales]) -> 22978.815 | E23: =SUMIF(Table3[Month Number], 2, Table3[Sales]) -> 20301.133 | F23: =SUM(Table2[[#This Row],[2014]:[2017]]) -> 59751.251
A24: March | B24: =SUMIF(Table12[Month Number], 3, Table12[Sales]) -> 55691.009 | C24: =SUMIF(Table11[Month Number], 3, Table11[Sales]) -> 38726.252 | D24: =SUMIF(Table10[Month Number], 3, Table10[Sales]) -> 51715.875 | E24: =SUMIF(Table3[Month Number], 3, Table3[Sales]) -> 58872.353 | F24: =SUM(Table2[[#This Row],[2014]:[2017]]) -> 205005.49
A25: April | B25: =SUMIF(Table12[Month Number], 4, Table12[Sales]) -> 28013.973 | C25: =SUMIF(Table11[Month Number], 4, Table11[Sales]) -> 34195.209 | D25: =SUMIF(Table10[Month Number], 4, Table10[Sales]) -> 38750.039 | E25: =SUMIF(Table3[Month Number], 4, Table3[Sales]) -> 36521.536 | F25: =SUM(Table2[[#This Row],[2014]:[2017]]) -> 137480.76
A26: May | B26: =SUMIF(Table12[Month Number], 5, Table12[Sales]) -> 23648.287 | C26: =SUMIF(Table11[Month Number], 5, Table11[Sales]) -> 30131.687 | D26: =SUMIF(Table10[Month Number], 5, Table10[Sales]) -> 56987.728 | E26: =SUMIF(Table3[Month Number], 5, Table3[Sales]) -> 44261.11 | F26: =SUM(Table2[[#This Row],[2014]:[2017]]) -> 155028.81
A27: June | B27: =SUMIF(Table12[Month Number], 6, Table12[Sales]) -> 34595.128 | C27: =SUMIF(Table11[Month Number], 6, Table11[Sales]) -> 24797.292 | D27: =SUMIF(Table10[Month Number], 6, Table10[Sales]) -> 40344.534 | E27: =SUMIF(Table3[Month Number], 6, Table3[Sales]) -> 52981.726 | F27: =SUM(Table2[[#This Row],[2014]:[2017]]) -> 152718.68
A28: July | B28: =SUMIF(Table12[Month Number], 7, Table12[Sales]) -> 33946.393 | C28: =SUMIF(Table11[Month Number], 7, Table11[Sales]) -> 28765.325 | D28: =SUMIF(Table10[Month Number], 7, Table10[Sales]) -> 39261.963 | E28: =SUMIF(Table3[Month Number], 7, Table3[Sales]) -> 45264.416 | F28: =SUM(Table2[[#This Row],[2014]:[2017]]) -> 147238.1
A29: August | B29: =SUMIF(Table12[Month Number], 8, Table12[Sales]) -> 27909.468 | C29: =SUMIF(Table11[Month Number], 8, Table11[Sales]) -> 36898.332 | D29: =SUMIF(Table10[Month Number], 8, Table10[Sales]) -> 31115.374 | E29: =SUMIF(Table3[Month Number], 8, Table3[Sales]) -> 63120.888 | F29: =SUM(Table2[[#This Row],[2014]:[2017]]) -> 159044.06
A30: September | B30: =SUMIF(Table12[Month Number], 9, Table12[Sales]) -> 81777.351 | C30: =SUMIF(Table11[Month Number], 9, Table11[Sales]) -> 64595.918 | D30: =SUMIF(Table10[Month Number], 9, Table10[Sales]) -> 73410.025 | E30: =SUMIF(Table3[Month Number], 9, Table3[Sales]) -> 87866.652 | F30: =SUM(Table2[[#This Row],[2014]:[2017]]) -> 307649.95
A31: October | B31: =SUMIF(Table12[Month Number], 10, Table12[Sales]) -> 31453.393 | C31: =SUMIF(Table11[Month Number], 10, Table11[Sales]) -> 31404.923 | D31: =SUMIF(Table10[Month Number], 10, Table10[Sales]) -> 59687.745 | E31: =SUMIF(Table3[Month Number], 10, Table3[Sales]) -> 77776.923 | F31: =SUM(Table2[[#This Row],[2014]:[2017]]) -> 200322.98
A32: November | B32: =SUMIF(Table12[Month Number], 11, Table12[Sales]) -> 78628.717 | C32: =SUMIF(Table11[Month Number], 11, Table11[Sales]) -> 75972.564 | D32: =SUMIF(Table10[Month Number], 11, Table10[Sales]) -> 79411.966 | E32: =SUMIF(Table3[Month Number], 11, Table3[Sales]) -> 118447.82 | F32: =SUM(Table2[[#This Row],[2014]:[2017]]) -> 352461.07
A33: December | B33: =SUMIF(Table12[Month Number], 12, Table12[Sales]) -> 69545.621 | C33: =SUMIF(Table11[Month Number], 12, Table11[Sales]) -> 74919.521 | D33: =SUMIF(Table10[Month Number], 12, Table10[Sales]) -> 96999.043 | E33: =SUMIF(Table3[Month Number], 12, Table3[Sales]) -> 83829.319 | F33: =SUM(Table2[[#This Row],[2014]:[2017]]) -> 325293.5
A34: Annual Sales | B34: =SUM(B22:B33) -> 483966.13 | C34: =SUM(C22:C33) -> 470532.51 | D34: =SUM(D22:D33) -> 609205.6 | E34: =SUM(E22:E33) -> 733215.26 | F34: =SUM(Table2[[#This Row],[2014]:[2017]]) -> 2296919.5
A35: Monthly Profit | B35: 2014 | C35: 2015 | D35: 2016 | E35: 2017 | F35: Grand Sales
A36: January | B36: =SUMIF(Table12[Month Number], 1, Table12[Profit]) -> 2450.1907 | C36: =SUMIF(Table11[Month Number], 1, Table11[Profit]) -> -3281.007 | D36: =SUMIF(Table10[Month Number], 1, Table10[Profit]) -> 2824.8233 | E36: =SUMIF(Table3[Month Number], 1, Table3[Profit]) -> 7140.4391 | F36: =SUM(Table25[[#This Row],[2014]:[2017]]) -> 9134.4461
A37: February | B37: =SUMIF(Table12[Month Number], 2, Table12[Profit]) -> 862.3084 | C37: =SUMIF(Table11[Month Number], 2, Table11[Profit]) -> 2813.8508 | D37: =SUMIF(Table10[Month Number], 2, Table10[Profit]) -> 5004.5795 | E37: =SUMIF(Table3[Month Number], 2, Table3[Profit]) -> 1613.872 | F37: =SUM(Table25[[#This Row],[2014]:[2017]]) -> 10294.611
A38: March | B38: =SUMIF(Table12[Month Number], 3, Table12[Profit]) -> 498.7299 | C38: =SUMIF(Table11[Month Number], 3, Table11[Profit]) -> 9732.0978 | D38: =SUMIF(Table10[Month Number], 3, Table10[Profit]) -> 3611.968 | E38: =SUMIF(Table3[Month Number], 3, Table3[Profit]) -> 14751.891 | F38: =SUM(Table25[[#This Row],[2014]:[2017]]) -> 28594.687
A39: April | B39: =SUMIF(Table12[Month Number], 4, Table12[Profit]) -> 3500.894 | C39: =SUMIF(Table11[Month Number], 4, Table11[Profit]) -> 4187.4962 | D39: =SUMIF(Table10[Month Number], 4, Table10[Profit]) -> 2977.8149 | E39: =SUMIF(Table3[Month Number], 4, Table3[Profit]) -> 933.29 | F39: =SUM(Table25[[#This Row],[2014]:[2017]]) -> 11599.495
A40: May | B40: =SUMIF(Table12[Month Number], 5, Table12[Profit]) -> 2738.7096 | C40: =SUMIF(Table11[Month Number], 5, Table11[Profit]) -> 4667.869 | D40: =SUMIF(Table10[Month Number], 5, Table10[Profit]) -> 8662.1464 | E40: =SUMIF(Table3[Month Number], 5, Table3[Profit]) -> 6342.5828 | F40: =SUM(Table25[[#This Row],[2014]:[2017]]) -> 22411.308
...

Sheet S.D. Analysis
A1: KPI | B1: 2014 | C1: 2015 | D1: 2016 | E1: 2017
A2: Total Sales | B2: =SUM(Table12[Sales]) -> 483966.13 | C2: =SUM(Table11[Sales]) -> 470532.51 | D2: =SUM(Table10[Sales]) -> 609205.6 | E2: =SUM(Table3[Sales]) -> 733215.26
A3: Total Profit | B3: =SUM(Table12[Profit]) -> 49556.033 | C3: =SUM(Table11[Profit]) -> 61618.604 | D3: =SUM(Table10[Profit]) -> 81795.174 | E3: =SUM(Table3[Profit]) -> 93439.27
A4: Profit Margin | B4: =B3/B2 -> 0.10239566 | C4: =C3/C2 -> 0.13095504 | D4: =D3/D2 -> 0.1342653 | E4: =E3/E2 -> 0.12743771
A5: Total Distinct Orders | B5: {=SUMPRODUCT(1/COUNTIF(Table12[Order ID],Table12[Order ID]))} -> 969 | C5: {=SUMPRODUCT(1/COUNTIF(Table11[Order ID],Table11[Order ID]))} -> 1038 | D5: {=SUMPRODUCT(1/COUNTIF(Table10[Order ID],Table10[Order ID]))} -> 1315 | E5: {=SUMPRODUCT(1/COUNTIF(Table3[Order ID],Table3[Order ID]))} -> 1687
A6: Average Order Value | B6: =B$2/B$5 -> 499.44905 | C6: =C$2/C$5 -> 453.30685 | D6: =D$2/D$5 -> 463.27422 | E6: =E$2/E$5 -> 434.62671
A11: Monthly Sales | B11: 2014 | C11: 2015 | D11: 2016 | E11: 2017
A12: Jan | B12: =SUMIF('2014_Clean_Data_Analysis'!D:D, 1,'2014_Clean_Data_Analysis'!T:T) -> 14236.895 | C12: =SUMIF('2015_Clean_Data_Analysis'!D:D, 1,'2015_Clean_Data_Analysis'!T:T) -> 18174.076 | D12: =SUMIF('2016_Clean_Data_Analysis'!D:D, 1,'2016_Clean_Data_Analysis'!T:T) -> 18542.491 | E12: =SUMIF('2017_Clean_Data_Analysis'!D:D, 1,'2017_Clean_Data_Analysis'!T:T) -> 43971.374
A13: Feb | B13: =SUMIF('2014_Clean_Data_Analysis'!D:D, 2,'2014_Clean_Data_Analysis'!T:T) -> 4519.892 | C13: =SUMIF('2015_Clean_Data_Analysis'!D:D, 2,'2015_Clean_Data_Analysis'!T:T) -> 11951.411 | D13: =SUMIF('2016_Clean_Data_Analysis'!D:D, 2,'2016_Clean_Data_Analysis'!T:T) -> 22978.815 | E13: =SUMIF('2017_Clean_Data_Analysis'!D:D, 2,'2017_Clean_Data_Analysis'!T:T) -> 20301.133
A14: Mar | B14: =SUMIF('2014_Clean_Data_Analysis'!D:D, 3,'2014_Clean_Data_Analysis'!T:T) -> 55691.009 | C14: =SUMIF('2015_Clean_Data_Analysis'!D:D, 3,'2015_Clean_Data_Analysis'!T:T) -> 38726.252 | D14: =SUMIF('2016_Clean_Data_Analysis'!D:D, 3,'2016_Clean_Data_Analysis'!T:T) -> 51715.875 | E14: =SUMIF('2017_Clean_Data_Analysis'!D:D, 3,'2017_Clean_Data_Analysis'!T:T) -> 58872.353
A15: Apr | B15: =SUMIF('2014_Clean_Data_Analysis'!D:D, 4,'2014_Clean_Data_Analysis'!T:T) -> 28013.973 | C15: =SUMIF('2015_Clean_Data_Analysis'!D:D, 4,'2015_Clean_Data_Analysis'!T:T) -> 34195.209 | D15: =SUMIF('2016_Clean_Data_Analysis'!D:D, 4,'2016_Clean_Data_Analysis'!T:T) -> 38750.039 | E15: =SUMIF('2017_Clean_Data_Analysis'!D:D, 4,'2017_Clean_Data_Analysis'!T:T) -> 36521.536
A16: May | B16: =SUMIF('2014_Clean_Data_Analysis'!D:D, 5,'2014_Clean_Data_Analysis'!T:T) -> 23648.287 | C16: =SUMIF('2015_Clean_Data_Analysis'!D:D, 5,'2015_Clean_Data_Analysis'!T:T) -> 30131.687 | D16: =SUMIF('2016_Clean_Data_Analysis'!D:D, 5,'2016_Clean_Data_Analysis'!T:T) -> 56987.728 | E16: =SUMIF('2017_Clean_Data_Analysis'!D:D, 5,'2017_Clean_Data_Analysis'!T:T) -> 44261.11
A17: Jun | B17: =SUMIF('2014_Clean_Data_Analysis'!D:D, 6,'2014_Clean_Data_Analysis'!T:T) -> 34595.128 | C17: =SUMIF('2015_Clean_Data_Analysis'!D:D, 6,'2015_Clean_Data_Analysis'!T:T) -> 24797.292 | D17: =SUMIF('2016_Clean_Data_Analysis'!D:D, 6,'2016_Clean_Data_Analysis'!T:T) -> 40344.534 | E17: =SUMIF('2017_Clean_Data_Analysis'!D:D, 6,'2017_Clean_Data_Analysis'!T:T) -> 52981.726
A18: Jul | B18: =SUMIF('2014_Clean_Data_Analysis'!D:D, 7,'2014_Clean_Data_Analysis'!T:T) -> 33946.393 | C18: =SUMIF('2015_Clean_Data_Analysis'!D:D, 7,'2015_Clean_Data_Analysis'!T:T) -> 28765.325 | D18: =SUMIF('2016_Clean_Data_Analysis'!D:D, 7,'2016_Clean_Data_Analysis'!T:T) -> 39261.963 | E18: =SUMIF('2017_Clean_Data_Analysis'!D:D, 7,'2017_Clean_Data_Analysis'!T:T) -> 45264.416
A19: Aug | B19: =SUMIF('2014_Clean_Data_Analysis'!D:D, 8,'2014_Clean_Data_Analysis'!T:T) -> 27909.468 | C19: =SUMIF('2015_Clean_Data_Analysis'!D:D, 8,'2015_Clean_Data_Analysis'!T:T) -> 36898.332 | D19: =SUMIF('2016_Clean_Data_Analysis'!D:D, 8,'2016_Clean_Data_Analysis'!T:T) -> 31115.374 | E19: =SUMIF('2017_Clean_Data_Analysis'!D:D, 8,'2017_Clean_Data_Analysis'!T:T) -> 63120.888
A20: Sep | B20: =SUMIF('2014_Clean_Data_Analysis'!D:D, 9,'2014_Clean_Data_Analysis'!T:T) -> 81777.351 | C20: =SUMIF('2015_Clean_Data_Analysis'!D:D, 9,'2015_Clean_Data_Analysis'!T:T) -> 64595.918 | D20: =SUMIF('2016_Clean_Data_Analysis'!D:D, 9,'2016_Clean_Data_Analysis'!T:T) -> 73410.025 | E20: =SUMIF('2017_Clean_Data_Analysis'!D:D, 9,'2017_Clean_Data_Analysis'!T:T) -> 87866.652
A21: Oct | B21: =SUMIF('2014_Clean_Data_Analysis'!D:D, 10,'2014_Clean_Data_Analysis'!T:T) -> 31453.393 | C21: =SUMIF('2015_Clean_Data_Analysis'!D:D, 10,'2015_Clean_Data_Analysis'!T:T) -> 31404.923 | D21: =SUMIF('2016_Clean_Data_Analysis'!D:D, 10,'2016_Clean_Data_Analysis'!T:T) -> 59687.745 | E21: =SUMIF('2017_Clean_Data_Analysis'!D:D, 10,'2017_Clean_Data_Analysis'!T:T) -> 77776.923
A22: Nov | B22: =SUMIF('2014_Clean_Data_Analysis'!D:D, 11,'2014_Clean_Data_Analysis'!T:T) -> 78628.717 | C22: =SUMIF('2015_Clean_Data_Analysis'!D:D, 11,'2015_Clean_Data_Analysis'!T:T) -> 75972.564 | D22: =SUMIF('2016_Clean_Data_Analysis'!D:D, 11,'2016_Clean_Data_Analysis'!T:T) -> 79411.966 | E22: =SUMIF('2017_Clean_Data_Analysis'!D:D, 11,'2017_Clean_Data_Analysis'!T:T) -> 118447.82
A23: Dec | B23: =SUMIF('2014_Clean_Data_Analysis'!D:D, 12,'2014_Clean_Data_Analysis'!T:T) -> 69545.621 | C23: =SUMIF('2015_Clean_Data_Analysis'!D:D, 12,'2015_Clean_Data_Analysis'!T:T) -> 74919.521 | D23: =SUMIF('2016_Clean_Data_Analysis'!D:D, 12,'2016_Clean_Data_Analysis'!T:T) -> 96999.043 | E23: =SUMIF('2017_Clean_Data_Analysis'!D:D, 12,'2017_Clean_Data_Analysis'!T:T) -> 83829.319
A24: Total | B24: =SUM(B$12:B$23) -> 483966.13 | C24: =SUM(C$12:C$23) -> 470532.51 | D24: =SUM(D$12:D$23) -> 609205.6 | E24: =SUM(E$12:E$23) -> 733215.26
A29: Monthly Profit | B29: 2014 | C29: 2015 | D29: 2016 | E29: 2017
A30: Jan | B30: =SUMIF('2014_Clean_Data_Analysis'!$D:$D, 1,'2014_Clean_Data_Analysis'!$U:$U) -> 2450.1907 | C30: =SUMIF('2015_Clean_Data_Analysis'!$D:$D, 1,'2015_Clean_Data_Analysis'!$U:$U) -> -3281.007 | D30: =SUMIF('2016_Clean_Data_Analysis'!$D:$D, 1,'2016_Clean_Data_Analysis'!$U:$U) -> 2824.8233 | E30: =SUMIF('2017_Clean_Data_Analysis'!$D:$D, 1,'2017_Clean_Data_Analysis'!$U:$U) -> 7140.4391
A31: Feb | B31: =SUMIF('2014_Clean_Data_Analysis'!$D:$D, 2,'2014_Clean_Data_Analysis'!$U:$U) -> 862.3084 | C31: =SUMIF('2015_Clean_Data_Analysis'!$D:$D, 2,'2015_Clean_Data_Analysis'!$U:$U) -> 2813.8508 | D31: =SUMIF('2016_Clean_Data_Analysis'!$D:$D, 2,'2016_Clean_Data_Analysis'!$U:$U) -> 5004.5795 | E31: =SUMIF('2017_Clean_Data_Analysis'!$D:$D, 2,'2017_Clean_Data_Analysis'!$U:$U) -> 1613.872
A32: Mar | B32: =SUMIF('2014_Clean_Data_Analysis'!$D:$D, 3,'2014_Clean_Data_Analysis'!$U:$U) -> 498.7299 | C32: =SUMIF('2015_Clean_Data_Analysis'!$D:$D, 3,'2015_Clean_Data_Analysis'!$U:$U) -> 9732.0978 | D32: =SUMIF('2016_Clean_Data_Analysis'!$D:$D, 3,'2016_Clean_Data_Analysis'!$U:$U) -> 3611.968 | E32: =SUMIF('2017_Clean_Data_Analysis'!$D:$D, 3,'2017_Clean_Data_Analysis'!$U:$U) -> 14751.891
A33: Apr | B33: =SUMIF('2014_Clean_Data_Analysis'!$D:$D, 4,'2014_Clean_Data_Analysis'!$U:$U) -> 3500.894 | C33: =SUMIF('2015_Clean_Data_Analysis'!$D:$D, 4,'2015_Clean_Data_Analysis'!$U:$U) -> 4187.4962 | D33: =SUMIF('2016_Clean_Data_Analysis'!$D:$D, 4,'2016_Clean_Data_Analysis'!$U:$U) -> 2977.8149 | E33: =SUMIF('2017_Clean_Data_Analysis'!$D:$D, 4,'2017_Clean_Data_Analysis'!$U:$U) -> 933.29
A34: May | B34: =SUMIF('2014_Clean_Data_Analysis'!$D:$D, 5,'2014_Clean_Data_Analysis'!$U:$U) -> 2738.7096 | C34: =SUMIF('2015_Clean_Data_Analysis'!$D:$D, 5,'2015_Clean_Data_Analysis'!$U:$U) -> 4667.869 | D34: =SUMIF('2016_Clean_Data_Analysis'!$D:$D, 5,'2016_Clean_Data_Analysis'!$U:$U) -> 8662.1464 | E34: =SUMIF('2017_Clean_Data_Analysis'!$D:$D, 5,'2017_Clean_Data_Analysis'!$U:$U) -> 6342.5828
A35: Jun | B35: =SUMIF('2014_Clean_Data_Analysis'!$D:$D, 6,'2014_Clean_Data_Analysis'!$U:$U) -> 4976.5244 | C35: =SUMIF('2015_Clean_Data_Analysis'!$D:$D, 6,'2015_Clean_Data_Analysis'!$U:$U) -> 3335.5572 | D35: =SUMIF('2016_Clean_Data_Analysis'!$D:$D, 6,'2016_Clean_Data_Analysis'!$U:$U) -> 4750.3781 | E35: =SUMIF('2017_Clean_Data_Analysis'!$D:$D, 6,'2017_Clean_Data_Analysis'!$U:$U) -> 8223.3357
A36: Jul | B36: =SUMIF('2014_Clean_Data_Analysis'!$D:$D, 7,'2014_Clean_Data_Analysis'!$U:$U) -> -841.4826 | C36: =SUMIF('2015_Clean_Data_Analysis'!$D:$D, 7,'2015_Clean_Data_Analysis'!$U:$U) -> 3288.6483 | D36: =SUMIF('2016_Clean_Data_Analysis'!$D:$D, 7,'2016_Clean_Data_Analysis'!$U:$U) -> 4432.8779 | E36: =SUMIF('2017_Clean_Data_Analysis'!$D:$D, 7,'2017_Clean_Data_Analysis'!$U:$U) -> 6952.6212
A37: Aug | B37: =SUMIF('2014_Clean_Data_Analysis'!$D:$D, 8,'2014_Clean_Data_Analysis'!$U:$U) -> 5318.105 | C37: =SUMIF('2015_Clean_Data_Analysis'!$D:$D, 8,'2015_Clean_Data_Analysis'!$U:$U) -> 5355.8084 | D37: =SUMIF('2016_Clean_Data_Analysis'!$D:$D, 8,'2016_Clean_Data_Analysis'!$U:$U) -> 2062.0693 | E37: =SUMIF('2017_Clean_Data_Analysis'!$D:$D, 8,'2017_Clean_Data_Analysis'!$U:$U) -> 9040.9557
A38: Sep | B38: =SUMIF('2014_Clean_Data_Analysis'!$D:$D, 9,'2014_Clean_Data_Analysis'!$U:$U) -> 8328.0994 | C38: =SUMIF('2015_Clean_Data_Analysis'!$D:$D, 9,'2015_Clean_Data_Analysis'!$U:$U) -> 8209.1627 | D38: =SUMIF('2016_Clean_Data_Analysis'!$D:$D, 9,'2016_Clean_Data_Analysis'!$U:$U) -> 9328.6576 | E38: =SUMIF('2017_Clean_Data_Analysis'!$D:$D, 9,'2017_Clean_Data_Analysis'!$U:$U) -> 10991.556
A39: Oct | B39: =SUMIF('2014_Clean_Data_Analysis'!$D:$D, 10,'2014_Clean_Data_Analysis'!$U:$U) -> 3448.2573 | C39: =SUMIF('2015_Clean_Data_Analysis'!$D:$D, 10,'2015_Clean_Data_Analysis'!$U:$U) -> 2817.366 | D39: =SUMIF('2016_Clean_Data_Analysis'!$D:$D, 10,'2016_Clean_Data_Analysis'!$U:$U) -> 16243.143 | E39: =SUMIF('2017_Clean_Data_Analysis'!$D:$D, 10,'2017_Clean_Data_Analysis'!$U:$U) -> 9275.2755
A40: Nov | B40: =SUMIF('2014_Clean_Data_Analysis'!$D:$D, 11,'2014_Clean_Data_Analysis'!$U:$U) -> 9292.1269 | C40: =SUMIF('2015_Clean_Data_Analysis'!$D:$D, 11,'2015_Clean_Data_Analysis'!$U:$U) -> 12474.788 | D40: =SUMIF('2016_Clean_Data_Analysis'!$D:$D, 11,'2016_Clean_Data_Analysis'!$U:$U) -> 4011.4075 | E40: =SUMIF('2017_Clean_Data_Analysis'!$D:$D, 11,'2017_Clean_Data_Analysis'!$U:$U) -> 9690.1037
A41: Dec | B41: =SUMIF('2014_Clean_Data_Analysis'!$D:$D, 12,'2014_Clean_Data_Analysis'!$U:$U) -> 8983.5699 | C41: =SUMIF('2015_Clean_Data_Analysis'!$D:$D, 12,'2015_Clean_Data_Analysis'!$U:$U) -> 8016.9659 | D41: =SUMIF('2016_Clean_Data_Analysis'!$D:$D, 12,'2016_Clean_Data_Analysis'!$U:$U) -> 17885.309 | E41: =SUMIF('2017_Clean_Data_Analysis'!$D:$D, 12,'2017_Clean_Data_Analysis'!$U:$U) -> 8483.3468
A42: Total | B42: =SUM(B$30:B$41) -> 49556.033 | C42: =SUM(C$30:C$41) -> 61618.604 | D42: =SUM(D$30:D$41) -> 81795.174 | E42: =SUM(E$30:E$41) -> 93439.27
B46: Quantity per Category
A47: Categroy | B47: 2014 | C47: 2015 | D47: 2016 | E47: 2017
A48: Furniture | B48: =SUMIF('2014_Clean_Data_Analysis'!$G:$G, 'S.D. Analysis'!$A48, '2014_Clean_Data_Analysis'!$K:$K) -> 1621 | C48: =SUMIF('2015_Clean_Data_Analysis'!$G:$G, 'S.D. Analysis'!$A48, '2015_Clean_Data_Analysis'!$K:$K) -> 1775 | D48: =SUMIF('2016_Clean_Data_Analysis'!$G:$G, 'S.D. Analysis'!$A48, '2016_Clean_Data_Analysis'!$K:$K) -> 2193 | E48: =SUMIF('2017_Clean_Data_Analysis'!$G:$G, 'S.D. Analysis'!$A48, '2017_Clean_Data_Analysis'!$K:$K) -> 2437
A49: Technology | B49: =SUMIF('2014_Clean_Data_Analysis'!$G:$G, 'S.D. Analysis'!$A49, '2014_Clean_Data_Analysis'!$K:$K) -> 1389 | C49: =SUMIF('2015_Clean_Data_Analysis'!$G:$G, 'S.D. Analysis'!$A49, '2015_Clean_Data_Analysis'!$K:$K) -> 1489 | D49: =SUMIF('2016_Clean_Data_Analysis'!$G:$G, 'S.D. Analysis'!$A49, '2016_Clean_Data_Analysis'!$K:$K) -> 1698 | E49: =SUMIF('2017_Clean_Data_Analysis'!$G:$G, 'S.D. Analysis'!$A49, '2017_Clean_Data_Analysis'!$K:$K) -> 2363
A50: Office Supplies | B50: =SUMIF('2014_Clean_Data_Analysis'!$G:$G, 'S.D. Analysis'!$A50, '2014_Clean_Data_Analysis'!$K:$K) -> 4569 | C50: =SUMIF('2015_Clean_Data_Analysis'!$G:$G, 'S.D. Analysis'!$A50, '2015_Clean_Data_Analysis'!$K:$K) -> 4715 | D50: =SUMIF('2016_Clean_Data_Analysis'!$G:$G, 'S.D. Analysis'!$A50, '2016_Clean_Data_Analysis'!$K:$K) -> 5946 | E50: =SUMIF('2017_Clean_Data_Analysis'!$G:$G, 'S.D. Analysis'!$A50, '2017_Clean_Data_Analysis'!$K:$K) -> 7676
A51: Total | B51: =SUM(B48:B50) -> 7579 | C51: =SUM(C48:C50) -> 7979 | D51: =SUM(D48:D50) -> 9837 | E51: =SUM(E48:E50) -> 12476
...
